
<xacro:macro name="cylinder_inertial" params="m r h">
  <inertial>
	 <mass value="${m}" />
	<inertia  ixx="${m*(3*r*r+h*h)/12}" ixy = "0" ixz = "0"
	iyy="${m*(3*r*r+h*h)/12}" iyz = "0"
	izz="${m*r*r/2}" /> 
  </inertial>
</xacro:macro>

<xacro:macro name="box_inertial" params="m w h d x">
  <inertial>
	 <mass value="${m}" />
	<inertia  ixx="${m*(h*h + d *d)/12}" 
	ixy = "0" ixz = "0"
	iyy="${m*(w*w+d*d)/12}" 
	iyz = "0"
	izz="${m*(h*h+w*w)/12}" 
	/> 

	<origin xyz="${x} 0 0"/>
  </inertial>
</xacro:macro>

<macro name="sphere_inertial" params="m r">
  <inertial>
	 <mass value="${m}" />
    <inertia  ixx="${2*m*r*r/5}" ixy = "0" ixz = "0"
      iyy="${2*m*r*r/5}" iyz = "0"
      izz="${2*m*r*r/5}"
    />
  </inertial>
</macro>

<xacro:macro name="default_inertial" params="mass">
  <inertial>
               <mass value="${mass}" />
               <inertia ixx="1.0" ixy="0.0" ixz="0.0"
                        iyy="1.0" iyz="0.0"
                        izz="1.0" />
  </inertial>
</xacro:macro>

	<!-- per https://en.wikipedia.org/wiki/List_of_moments_of_inertia 
	  ixx = m/12(h * h  + d * d)
	  iyy = m/12(w * w  + d * d)
	  izz= m/12(w * w  + h * h)
	 -->

       <!-- per https://answers.ros.org/question/39107/urdf-link-mass-inertia-prop 
		origin should be from baselink origin to center of mass.
		which  is half way from axil (baselink) to caster attachment
		which I estimate is 9 inches -->

  <macro name="wheel" params="lr tY">

    <link name="${lr}_wheel">
      <collision>
        <origin xyz="0 0 0" rpy="0 ${PI/2} ${PI/2}" />
        <geometry>
          <cylinder length="${wheelWidth}" radius="${wheelRadius}"/>
        </geometry>
      </collision>

      <visual>
        <origin xyz="0 0 0" rpy="0 ${PI/2} ${PI/2}" />
        <geometry>
          <cylinder length="${wheelWidth}" radius="${wheelRadius}"/>
        </geometry>
        <material name="black"/>
      </visual>

      <inertial>
        <origin xyz="0 0 0" rpy="0 ${PI/2} ${PI/2}" />
        <mass value="${wheelMass}"/>
        <cylinder_inertia m="${wheelMass}" r="${wheelRadius}" h="${wheelWidth}"/>
      </inertial>
    </link>

    <gazebo reference="${lr}_wheel">
      <mu1 value="1.0"/>
      <mu2 value="1.0"/>
      <kp  value="10000000.0" />
      <kd  value="1.0" />
      <fdir1 value="1 0 0"/>
      <material>Gazebo/Black</material>
    </gazebo>


    <joint name="${lr}_wheel_hinge" type="continuous">
      <parent link="chassis"/>
      <child link="${lr}_wheel"/>
    <origin xyz="${-wheelPos+chassisLength/2} ${tY*wheelWidth/2+tY*chassisWidth/2} ${wheelRadius}" rpy="0 0 0" />
      <axis xyz="0 1 0" rpy="0 0 0" />
      <limit effort="10000" velocity="10000"/>
      <joint_properties damping="0.0" friction="0.0"/>
    </joint>


    <transmission name="${lr}_trans">
      <type>transmission_interface/SimpleTransmission</type>
      <joint name="${lr}_wheel_hinge">
        <hardwareInterface>EffortJointInterface</hardwareInterface>
      </joint>
      <actuator name="${lr}Motor">
        <hardwareInterface>EffortJointInterface</hardwareInterface>
        <mechanicalReduction>10</mechanicalReduction>
      </actuator>
    </transmission>

  </macro>

